Workbook
Name 產品: #REF!
Name 組合: 成本表_鎖匙扣!$A:$A
Name 組合: 報價表_鎖匙扣!$A:$A

Sheet 銷售_2026
A1: Free_Handsss_2026 | D1: 總營收: | E1: =40458+65676+139960+P1 -> 268173 | I1: 打印總數: | J1: =SUM(J3:J29) -> 43 | M1: =SUM(M3:M27) -> 28980 | N1: =SUM(N3:O29) -> 10670 | O1: =SUM(O3:O29) -> 0 | P1: =SUMIF(M3:M1017, ">0", P3:P1017) -> 22079 | Q1: =P1/M1 -> 0.76187026
A2: S/N | B2: 日期 | C2: 客人 | D2: 刻名 | E2: 刻日 | F2: 對象 | G2: 手腳 | H2: 產品 | I2: 材料 | J2: 數量 | K2: 組合 | L2: 批量 | M2: 金額 | N2: 成本 | O2: 調整 | P2: 營收 | Q2: 備注
A3: 1 | B3: 46029 | C3: Jasmine | D3: Yuna | E3: 1107 | F3: 嬰兒 | G3: 腳 | H3: 鎖匙扣 | I3: 不锈鋼 | J3: 4 | K3: (已掃手) | L3: 第31批 | M3: 2000 | N3: {=IF(鎖售表[[#This Row],[產品]]="鎖匙扣", _xlfn.XLOOKUP(鎖售表[[#This Row],[對象]]&鎖售表[[#This Row],[材料]]&鎖售表[[#This Row],[數量]], 成本表_鎖匙扣!$A$2:$A$100&成本表_鎖匙扣!$C$2:$C$100&成本表_鎖匙扣!$D$2:$D$100, 成本表_鎖匙扣!$E$2:$E$100, 0), _xlfn.XLOOKUP(鎖售表[[#This Row],[對象]]&鎖售表[[#This Row],[產品]]&鎖售表[[#This Row],[材料]]&鎖售表[[#This Row],[數量]], 成本表_吊飾!$A$2:$A$100&成本表_吊飾!$B$2:$B$100&成本表_吊飾!$C$2:$C$100&成本表_吊飾!$D$2:$D$100, 成本表_吊飾!$E$2:$E$100, 0) ) + IF(ISNUMBER(M3), ( IF(AND(A4="",M4=""),N4,0) + IF(AND(A4="",M4="",A5="",M5=""),N5,0) + IF(AND(A4="",M4="",A5="",M5="",A6="",M6=""),N6,0) + IF(AND(A4="",M4="",A5="",M5="",A6="",M6="",A7="",M7=""),N7,0) + IF(AND(A4="",M4="",A5="",M5="",A6="",M6="",A7="",M7="",A8="",M8=""),N8,0) + IF(AND(A4="",M4="",A5="",M5="",A6="",M6="",A7="",M7="",A8="",M8="",A9="",M9=""),N9,0) + IF(AND(A4="",M4="",A5="",M5="",A6="",M6="",A7="",M7="",A8="",M8="",A9="",M9="",A10="",M10=""),N10,0) + IF(AND(A4="",M4="",A5="",M5="",A6="",M6="",A7="",M7="",A8="",M8="",A9="",M9="",A10="",M10="",A11="",M11=""),N11,0) ) - ( INT( ( (H3="吊飾") + (IF(AND(A4="",M4=""),H4="吊飾",0)) + (IF(AND(A4="",M4="",A5="",M5=""),H5="吊飾",0)) + (IF(AND(A4="",M4="",A5="",M5="",A6="",M6=""),H6="吊飾",0)) + (IF(AND(A4="",M4="",A5="",M5="",A6="",M6="",A7="",M7=""),H7="吊飾",0)) + (IF(AND(A4="",M4="",A5="",M5="",A6="",M6="",A7="",M7="",A8="",M8=""),H8="吊飾",0)) + (IF(AND(A4="",M4="",A5="",M5="",A6="",M6="",A7="",M7="",A8="",M8="",A9="",M9=""),H9="吊飾",0)) + (IF(AND(A4="",M4="",A5="",M5="",A6="",M6="",A7="",M7="",A8="",M8="",A9="",M9="",A10="",M10=""),H10="吊飾",0)) ) / 2 ) * 220 + MAX(0, ( (H3="鎖匙扣") + (IF(AND(A4="",M4=""),H4="鎖匙扣",0)) + (IF(AND(A4="",M4="",A5="",M5=""),H5="鎖匙扣",0)) + (IF(AND(A4="",M4="",A5="",M5="",A6="",M6=""),H6="鎖匙扣",0)) + (IF(AND(A4="",M4="",A5="",M5="",A6="",M6="",A7="",M7=""),H7="鎖匙扣",0)) + (IF(AND(A4="",M4="",A5="",M5="",A6="",M6="",A7="",M7="",A8="",M8=""),H8="鎖匙扣",0)) + (IF(AND(A4="",M4="",A5="",M5="",A6="",M6="",A7="",M7="",A8="",M8="",A9="",M9=""),H9="鎖匙扣",0)) + (IF(AND(A4="",M4="",A5="",M5="",A6="",M6="",A7="",M7="",A8="",M8="",A9="",M9="",A10="",M10=""),H10="鎖匙扣",0)) ) - 1 ) * 20 ), 0 )} -> 500 | P3: =IF(ISNUMBER(M3), M3 - N3 - (O3 + IF(AND(A4="",M4=""),O4,0) + IF(AND(A4="",M4="",A5="",M5=""),O5,0) + IF(AND(A4="",M4="",A5="",M5="",A6="",M6=""),O6,0) + IF(AND(A4="",M4="",A5="",M5="",A6="",M6="",A7="",M7=""),O7,0) + IF(AND(A4="",M4="",A5="",M5="",A6="",M6="",A7="",M7="",A8="",M8=""),O8,0) + IF(AND(A4="",M4="",A5="",M5="",A6="",M6="",A7="",M7="",A8="",M8="",A9="",M9=""),O9,0) + IF(AND(A4="",M4="",A5="",M5="",A6="",M6="",A7="",M7="",A8="",M8="",A9="",M9="",A10="",M10=""),O10,0) + IF(AND(A4="",M4="",A5="",M5="",A6="",M6="",A7="",M7="",A8="",M8="",A9="",M9="",A10="",M10="",A11="",M11=""),O11,0) + IF(AND(A4="",M4="",A5="",M5="",A6="",M6="",A7="",M7="",A8="",M8="",A9="",M9="",A10="",M10="",A11="",M11="",A12="",M12=""),O12,0) ), -N3 - O3 ) -> 1500 | Q3: Done | S3: 2 代表畫完妥當
A4: 2 | B4: 46041 | C4: Akira | D4: LUCA | E4: 1223 | F4: 嬰兒 | G4: 手 | H4: 鎖匙扣 | I4: 不锈鋼 | J4: 1 | L4: 第31批 | M4: 3340 | N4: {=IF(鎖售表[[#This Row],[產品]]="鎖匙扣", _xlfn.XLOOKUP(鎖售表[[#This Row],[對象]]&鎖售表[[#This Row],[材料]]&鎖售表[[#This Row],[數量]], 成本表_鎖匙扣!$A$2:$A$100&成本表_鎖匙扣!$C$2:$C$100&成本表_鎖匙扣!$D$2:$D$100, 成本表_鎖匙扣!$E$2:$E$100, 0), _xlfn.XLOOKUP(鎖售表[[#This Row],[對象]]&鎖售表[[#This Row],[產品]]&鎖售表[[#This Row],[材料]]&鎖售表[[#This Row],[數量]], 成本表_吊飾!$A$2:$A$100&成本表_吊飾!$B$2:$B$100&成本表_吊飾!$C$2:$C$100&成本表_吊飾!$D$2:$D$100, 成本表_吊飾!$E$2:$E$100, 0) ) + IF(ISNUMBER(M4), ( IF(AND(A5="",M5=""),N5,0) + IF(AND(A5="",M5="",A6="",M6=""),N6,0) + IF(AND(A5="",M5="",A6="",M6="",A7="",M7=""),N7,0) + IF(AND(A5="",M5="",A6="",M6="",A7="",M7="",A8="",M8=""),N8,0) + IF(AND(A5="",M5="",A6="",M6="",A7="",M7="",A8="",M8="",A9="",M9=""),N9,0) + IF(AND(A5="",M5="",A6="",M6="",A7="",M7="",A8="",M8="",A9="",M9="",A10="",M10=""),N10,0) + IF(AND(A5="",M5="",A6="",M6="",A7="",M7="",A8="",M8="",A9="",M9="",A10="",M10="",A11="",M11=""),N11,0) + IF(AND(A5="",M5="",A6="",M6="",A7="",M7="",A8="",M8="",A9="",M9="",A10="",M10="",A11="",M11="",A12="",M12=""),N12,0) ) - ( INT( ( (H4="吊飾") + (IF(AND(A5="",M5=""),H5="吊飾",0)) + (IF(AND(A5="",M5="",A6="",M6=""),H6="吊飾",0)) + (IF(AND(A5="",M5="",A6="",M6="",A7="",M7=""),H7="吊飾",0)) + (IF(AND(A5="",M5="",A6="",M6="",A7="",M7="",A8="",M8=""),H8="吊飾",0)) + (IF(AND(A5="",M5="",A6="",M6="",A7="",M7="",A8="",M8="",A9="",M9=""),H9="吊飾",0)) + (IF(AND(A5="",M5="",A6="",M6="",A7="",M7="",A8="",M8="",A9="",M9="",A10="",M10=""),H10="吊飾",0)) + (IF(AND(A5="",M5="",A6="",M6="",A7="",M7="",A8="",M8="",A9="",M9="",A10="",M10="",A11="",M11=""),H11="吊飾",0)) ) / 2 ) * 220 + MAX(0, ( (H4="鎖匙扣") + (IF(AND(A5="",M5=""),H5="鎖匙扣",0)) + (IF(AND(A5="",M5="",A6="",M6=""),H6="鎖匙扣",0)) + (IF(AND(A5="",M5="",A6="",M6="",A7="",M7=""),H7="鎖匙扣",0)) + (IF(AND(A5="",M5="",A6="",M6="",A7="",M7="",A8="",M8=""),H8="鎖匙扣",0)) + (IF(AND(A5="",M5="",A6="",M6="",A7="",M7="",A8="",M8="",A9="",M9=""),H9="鎖匙扣",0)) + (IF(AND(A5="",M5="",A6="",M6="",A7="",M7="",A8="",M8="",A9="",M9="",A10="",M10=""),H10="鎖匙扣",0)) + (IF(AND(A5="",M5="",A6="",M6="",A7="",M7="",A8="",M8="",A9="",M9="",A10="",M10="",A11="",M11=""),H11="鎖匙扣",0)) ) - 1 ) * 20 ), 0 )} -> 680 | P4: =IF(ISNUMBER(M4), M4 - N4 - (O4 + IF(AND(A5="",M5=""),O5,0) + IF(AND(A5="",M5="",A6="",M6=""),O6,0) + IF(AND(A5="",M5="",A6="",M6="",A7="",M7=""),O7,0) + IF(AND(A5="",M5="",A6="",M6="",A7="",M7="",A8="",M8=""),O8,0) + IF(AND(A5="",M5="",A6="",M6="",A7="",M7="",A8="",M8="",A9="",M9=""),O9,0) + IF(AND(A5="",M5="",A6="",M6="",A7="",M7="",A8="",M8="",A9="",M9="",A10="",M10=""),O10,0) + IF(AND(A5="",M5="",A6="",M6="",A7="",M7="",A8="",M8="",A9="",M9="",A10="",M10="",A11="",M11=""),O11,0) + IF(AND(A5="",M5="",A6="",M6="",A7="",M7="",A8="",M8="",A9="",M9="",A10="",M10="",A11="",M11="",A12="",M12=""),O12,0) + IF(AND(A5="",M5="",A6="",M6="",A7="",M7="",A8="",M8="",A9="",M9="",A10="",M10="",A11="",M11="",A12="",M12="",A13="",M13=""),O13,0) ), -N4 - O4 ) -> 2660 | Q4: Done | S4: 3 代表廠商打印
F5: 嬰兒 | G5: 手 | H5: 鎖匙扣 | I5: 不锈鋼 | J5: 1 | L5: 第31批 | N5: {=IF(鎖售表[[#This Row],[產品]]="鎖匙扣", _xlfn.XLOOKUP(鎖售表[[#This Row],[對象]]&鎖售表[[#This Row],[材料]]&鎖售表[[#This Row],[數量]], 成本表_鎖匙扣!$A$2:$A$100&成本表_鎖匙扣!$C$2:$C$100&成本表_鎖匙扣!$D$2:$D$100, 成本表_鎖匙扣!$E$2:$E$100, 0), _xlfn.XLOOKUP(鎖售表[[#This Row],[對象]]&鎖售表[[#This Row],[產品]]&鎖售表[[#This Row],[材料]]&鎖售表[[#This Row],[數量]], 成本表_吊飾!$A$2:$A$100&成本表_吊飾!$B$2:$B$100&成本表_吊飾!$C$2:$C$100&成本表_吊飾!$D$2:$D$100, 成本表_吊飾!$E$2:$E$100, 0) ) + IF(ISNUMBER(M5), ( IF(AND(A6="",M6=""),N6,0) + IF(AND(A6="",M6="",A7="",M7=""),N7,0) + IF(AND(A6="",M6="",A7="",M7="",A8="",M8=""),N8,0) + IF(AND(A6="",M6="",A7="",M7="",A8="",M8="",A9="",M9=""),N9,0) + IF(AND(A6="",M6="",A7="",M7="",A8="",M8="",A9="",M9="",A10="",M10=""),N10,0) + IF(AND(A6="",M6="",A7="",M7="",A8="",M8="",A9="",M9="",A10="",M10="",A11="",M11=""),N11,0) + IF(AND(A6="",M6="",A7="",M7="",A8="",M8="",A9="",M9="",A10="",M10="",A11="",M11="",A12="",M12=""),N12,0) + IF(AND(A6="",M6="",A7="",M7="",A8="",M8="",A9="",M9="",A10="",M10="",A11="",M11="",A12="",M12="",A13="",M13=""),N13,0) ) - ( INT( ( (H5="吊飾") + (IF(AND(A6="",M6=""),H6="吊飾",0)) + (IF(AND(A6="",M6="",A7="",M7=""),H7="吊飾",0)) + (IF(AND(A6="",M6="",A7="",M7="",A8="",M8=""),H8="吊飾",0)) + (IF(AND(A6="",M6="",A7="",M7="",A8="",M8="",A9="",M9=""),H9="吊飾",0)) + (IF(AND(A6="",M6="",A7="",M7="",A8="",M8="",A9="",M9="",A10="",M10=""),H10="吊飾",0)) + (IF(AND(A6="",M6="",A7="",M7="",A8="",M8="",A9="",M9="",A10="",M10="",A11="",M11=""),H11="吊飾",0)) + (IF(AND(A6="",M6="",A7="",M7="",A8="",M8="",A9="",M9="",A10="",M10="",A11="",M11="",A12="",M12=""),H12="吊飾",0)) ) / 2 ) * 220 + MAX(0, ( (H5="鎖匙扣") + (IF(AND(A6="",M6=""),H6="鎖匙扣",0)) + (IF(AND(A6="",M6="",A7="",M7=""),H7="鎖匙扣",0)) + (IF(AND(A6="",M6="",A7="",M7="",A8="",M8=""),H8="鎖匙扣",0)) + (IF(AND(A6="",M6="",A7="",M7="",A8="",M8="",A9="",M9=""),H9="鎖匙扣",0)) + (IF(AND(A6="",M6="",A7="",M7="",A8="",M8="",A9="",M9="",A10="",M10=""),H10="鎖匙扣",0)) + (IF(AND(A6="",M6="",A7="",M7="",A8="",M8="",A9="",M9="",A10="",M10="",A11="",M11=""),H11="鎖匙扣",0)) + (IF(AND(A6="",M6="",A7="",M7="",A8="",M8="",A9="",M9="",A10="",M10="",A11="",M11="",A12="",M12=""),H12="鎖匙扣",0)) ) - 1 ) * 20 ), 0 )} -> 185 | P5: =IF(ISNUMBER(M5), M5 - N5 - (O5 + IF(AND(A6="",M6=""),O6,0) + IF(AND(A6="",M6="",A7="",M7=""),O7,0) + IF(AND(A6="",M6="",A7="",M7="",A8="",M8=""),O8,0) + IF(AND(A6="",M6="",A7="",M7="",A8="",M8="",A9="",M9=""),O9,0) + IF(AND(A6="",M6="",A7="",M7="",A8="",M8="",A9="",M9="",A10="",M10=""),O10,0) + IF(AND(A6="",M6="",A7="",M7="",A8="",M8="",A9="",M9="",A10="",M10="",A11="",M11=""),O11,0) + IF(AND(A6="",M6="",A7="",M7="",A8="",M8="",A9="",M9="",A10="",M10="",A11="",M11="",A12="",M12=""),O12,0) + IF(AND(A6="",M6="",A7="",M7="",A8="",M8="",A9="",M9="",A10="",M10="",A11="",M11="",A12="",M12="",A13="",M13=""),O13,0) + IF(AND(A6="",M6="",A7="",M7="",A8="",M8="",A9="",M9="",A10="",M10="",A11="",M11="",A12="",M12="",A13="",M13="",A14="",M14=""),O14,0) ), -N5 - O5 ) -> -185 | Q5: Done
F6: 嬰兒 | G6: 腳 | H6: 鎖匙扣 | I6: 不锈鋼 | J6: 1 | L6: 第31批 | N6: {=IF(鎖售表[[#This Row],[產品]]="鎖匙扣", _xlfn.XLOOKUP(鎖售表[[#This Row],[對象]]&鎖售表[[#This Row],[材料]]&鎖售表[[#This Row],[數量]], 成本表_鎖匙扣!$A$2:$A$100&成本表_鎖匙扣!$C$2:$C$100&成本表_鎖匙扣!$D$2:$D$100, 成本表_鎖匙扣!$E$2:$E$100, 0), _xlfn.XLOOKUP(鎖售表[[#This Row],[對象]]&鎖售表[[#This Row],[產品]]&鎖售表[[#This Row],[材料]]&鎖售表[[#This Row],[數量]], 成本表_吊飾!$A$2:$A$100&成本表_吊飾!$B$2:$B$100&成本表_吊飾!$C$2:$C$100&成本表_吊飾!$D$2:$D$100, 成本表_吊飾!$E$2:$E$100, 0) ) + IF(ISNUMBER(M6), ( IF(AND(A7="",M7=""),N7,0) + IF(AND(A7="",M7="",A8="",M8=""),N8,0) + IF(AND(A7="",M7="",A8="",M8="",A9="",M9=""),N9,0) + IF(AND(A7="",M7="",A8="",M8="",A9="",M9="",A10="",M10=""),N10,0) + IF(AND(A7="",M7="",A8="",M8="",A9="",M9="",A10="",M10="",A11="",M11=""),N11,0) + IF(AND(A7="",M7="",A8="",M8="",A9="",M9="",A10="",M10="",A11="",M11="",A12="",M12=""),N12,0) + IF(AND(A7="",M7="",A8="",M8="",A9="",M9="",A10="",M10="",A11="",M11="",A12="",M12="",A13="",M13=""),N13,0) + IF(AND(A7="",M7="",A8="",M8="",A9="",M9="",A10="",M10="",A11="",M11="",A12="",M12="",A13="",M13="",A14="",M14=""),N14,0) ) - ( INT( ( (H6="吊飾") + (IF(AND(A7="",M7=""),H7="吊飾",0)) + (IF(AND(A7="",M7="",A8="",M8=""),H8="吊飾",0)) + (IF(AND(A7="",M7="",A8="",M8="",A9="",M9=""),H9="吊飾",0)) + (IF(AND(A7="",M7="",A8="",M8="",A9="",M9="",A10="",M10=""),H10="吊飾",0)) + (IF(AND(A7="",M7="",A8="",M8="",A9="",M9="",A10="",M10="",A11="",M11=""),H11="吊飾",0)) + (IF(AND(A7="",M7="",A8="",M8="",A9="",M9="",A10="",M10="",A11="",M11="",A12="",M12=""),H12="吊飾",0)) + (IF(AND(A7="",M7="",A8="",M8="",A9="",M9="",A10="",M10="",A11="",M11="",A12="",M12="",A13="",M13=""),H13="吊飾",0)) ) / 2 ) * 220 + MAX(0, ( (H6="鎖匙扣") + (IF(AND(A7="",M7=""),H7="鎖匙扣",0)) + (IF(AND(A7="",M7="",A8="",M8=""),H8="鎖匙扣",0)) + (IF(AND(A7="",M7="",A8="",M8="",A9="",M9=""),H9="鎖匙扣",0)) + (IF(AND(A7="",M7="",A8="",M8="",A9="",M9="",A10="",M10=""),H10="鎖匙扣",0)) + (IF(AND(A7="",M7="",A8="",M8="",A9="",M9="",A10="",M10="",A11="",M11=""),H11="鎖匙扣",0)) + (IF(AND(A7="",M7="",A8="",M8="",A9="",M9="",A10="",M10="",A11="",M11="",A12="",M12=""),H12="鎖匙扣",0)) + (IF(AND(A7="",M7="",A8="",M8="",A9="",M9="",A10="",M10="",A11="",M11="",A12="",M12="",A13="",M13=""),H13="鎖匙扣",0)) ) - 1 ) * 20 ), 0 )} -> 185 | P6: =IF(ISNUMBER(M6), M6 - N6 - (O6 + IF(AND(A7="",M7=""),O7,0) + IF(AND(A7="",M7="",A8="",M8=""),O8,0) + IF(AND(A7="",M7="",A8="",M8="",A9="",M9=""),O9,0) + IF(AND(A7="",M7="",A8="",M8="",A9="",M9="",A10="",M10=""),O10,0) + IF(AND(A7="",M7="",A8="",M8="",A9="",M9="",A10="",M10="",A11="",M11=""),O11,0) + IF(AND(A7="",M7="",A8="",M8="",A9="",M9="",A10="",M10="",A11="",M11="",A12="",M12=""),O12,0) + IF(AND(A7="",M7="",A8="",M8="",A9="",M9="",A10="",M10="",A11="",M11="",A12="",M12="",A13="",M13=""),O13,0) + IF(AND(A7="",M7="",A8="",M8="",A9="",M9="",A10="",M10="",A11="",M11="",A12="",M12="",A13="",M13="",A14="",M14=""),O14,0) + IF(AND(A7="",M7="",A8="",M8="",A9="",M9="",A10="",M10="",A11="",M11="",A12="",M12="",A13="",M13="",A14="",M14="",A15="",M15=""),O15,0) ), -N6 - O6 ) -> -185 | Q6: Done
F7: 嬰兒 | G7: 腳 | H7: 鎖匙扣 | I7: 不锈鋼 | J7: 1 | L7: 第31批 | N7: {=IF(鎖售表[[#This Row],[產品]]="鎖匙扣", _xlfn.XLOOKUP(鎖售表[[#This Row],[對象]]&鎖售表[[#This Row],[材料]]&鎖售表[[#This Row],[數量]], 成本表_鎖匙扣!$A$2:$A$100&成本表_鎖匙扣!$C$2:$C$100&成本表_鎖匙扣!$D$2:$D$100, 成本表_鎖匙扣!$E$2:$E$100, 0), _xlfn.XLOOKUP(鎖售表[[#This Row],[對象]]&鎖售表[[#This Row],[產品]]&鎖售表[[#This Row],[材料]]&鎖售表[[#This Row],[數量]], 成本表_吊飾!$A$2:$A$100&成本表_吊飾!$B$2:$B$100&成本表_吊飾!$C$2:$C$100&成本表_吊飾!$D$2:$D$100, 成本表_吊飾!$E$2:$E$100, 0) ) + IF(ISNUMBER(M7), ( IF(AND(A8="",M8=""),N8,0) + IF(AND(A8="",M8="",A9="",M9=""),N9,0) + IF(AND(A8="",M8="",A9="",M9="",A10="",M10=""),N10,0) + IF(AND(A8="",M8="",A9="",M9="",A10="",M10="",A11="",M11=""),N11,0) + IF(AND(A8="",M8="",A9="",M9="",A10="",M10="",A11="",M11="",A12="",M12=""),N12,0) + IF(AND(A8="",M8="",A9="",M9="",A10="",M10="",A11="",M11="",A12="",M12="",A13="",M13=""),N13,0) + IF(AND(A8="",M8="",A9="",M9="",A10="",M10="",A11="",M11="",A12="",M12="",A13="",M13="",A14="",M14=""),N14,0) + IF(AND(A8="",M8="",A9="",M9="",A10="",M10="",A11="",M11="",A12="",M12="",A13="",M13="",A14="",M14="",A15="",M15=""),N15,0) ) - ( INT( ( (H7="吊飾") + (IF(AND(A8="",M8=""),H8="吊飾",0)) + (IF(AND(A8="",M8="",A9="",M9=""),H9="吊飾",0)) + (IF(AND(A8="",M8="",A9="",M9="",A10="",M10=""),H10="吊飾",0)) + (IF(AND(A8="",M8="",A9="",M9="",A10="",M10="",A11="",M11=""),H11="吊飾",0)) + (IF(AND(A8="",M8="",A9="",M9="",A10="",M10="",A11="",M11="",A12="",M12=""),H12="吊飾",0)) + (IF(AND(A8="",M8="",A9="",M9="",A10="",M10="",A11="",M11="",A12="",M12="",A13="",M13=""),H13="吊飾",0)) + (IF(AND(A8="",M8="",A9="",M9="",A10="",M10="",A11="",M11="",A12="",M12="",A13="",M13="",A14="",M14=""),H14="吊飾",0)) ) / 2 ) * 220 + MAX(0, ( (H7="鎖匙扣") + (IF(AND(A8="",M8=""),H8="鎖匙扣",0)) + (IF(AND(A8="",M8="",A9="",M9=""),H9="鎖匙扣",0)) + (IF(AND(A8="",M8="",A9="",M9="",A10="",M10=""),H10="鎖匙扣",0)) + (IF(AND(A8="",M8="",A9="",M9="",A10="",M10="",A11="",M11=""),H11="鎖匙扣",0)) + (IF(AND(A8="",M8="",A9="",M9="",A10="",M10="",A11="",M11="",A12="",M12=""),H12="鎖匙扣",0)) + (IF(AND(A8="",M8="",A9="",M9="",A10="",M10="",A11="",M11="",A12="",M12="",A13="",M13=""),H13="鎖匙扣",0)) + (IF(AND(A8="",M8="",A9="",M9="",A10="",M10="",A11="",M11="",A12="",M12="",A13="",M13="",A14="",M14=""),H14="鎖匙扣",0)) ) - 1 ) * 20 ), 0 )} -> 185 | P7: =IF(ISNUMBER(M7), M7 - N7 - (O7 + IF(AND(A8="",M8=""),O8,0) + IF(AND(A8="",M8="",A9="",M9=""),O9,0) + IF(AND(A8="",M8="",A9="",M9="",A10="",M10=""),O10,0) + IF(AND(A8="",M8="",A9="",M9="",A10="",M10="",A11="",M11=""),O11,0) + IF(AND(A8="",M8="",A9="",M9="",A10="",M10="",A11="",M11="",A12="",M12=""),O12,0) + IF(AND(A8="",M8="",A9="",M9="",A10="",M10="",A11="",M11="",A12="",M12="",A13="",M13=""),O13,0) + IF(AND(A8="",M8="",A9="",M9="",A10="",M10="",A11="",M11="",A12="",M12="",A13="",M13="",A14="",M14=""),O14,0) + IF(AND(A8="",M8="",A9="",M9="",A10="",M10="",A11="",M11="",A12="",M12="",A13="",M13="",A14="",M14="",A15="",M15=""),O15,0) + IF(AND(A8="",M8="",A9="",M9="",A10="",M10="",A11="",M11="",A12="",M12="",A13="",M13="",A14="",M14="",A15="",M15="",A16="",M16=""),O16,0) ), -N7 - O7 ) -> -185 | Q7: Done
A8: 3 | B8: 46042 | C8: WingLee | D8: LY | E8: 6.12 | F8: 嬰兒(P) | G8: 手 | H8: 鎖匙扣 | I8: 不锈鋼 | J8: 1 | K8: 右手 | L8: 第32批 | M8: 2160 | N8: {=IF(鎖售表[[#This Row],[產品]]="鎖匙扣", _xlfn.XLOOKUP(鎖售表[[#This Row],[對象]]&鎖售表[[#This Row],[材料]]&鎖售表[[#This Row],[數量]], 成本表_鎖匙扣!$A$2:$A$100&成本表_鎖匙扣!$C$2:$C$100&成本表_鎖匙扣!$D$2:$D$100, 成本表_鎖匙扣!$E$2:$E$100, 0), _xlfn.XLOOKUP(鎖售表[[#This Row],[對象]]&鎖售表[[#This Row],[產品]]&鎖售表[[#This Row],[材料]]&鎖售表[[#This Row],[數量]], 成本表_吊飾!$A$2:$A$100&成本表_吊飾!$B$2:$B$100&成本表_吊飾!$C$2:$C$100&成本表_吊飾!$D$2:$D$100, 成本表_吊飾!$E$2:$E$100, 0) ) + IF(ISNUMBER(M8), ( IF(AND(A9="",M9=""),N9,0) + IF(AND(A9="",M9="",A10="",M10=""),N10,0) + IF(AND(A9="",M9="",A10="",M10="",A11="",M11=""),N11,0) + IF(AND(A9="",M9="",A10="",M10="",A11="",M11="",A12="",M12=""),N12,0) + IF(AND(A9="",M9="",A10="",M10="",A11="",M11="",A12="",M12="",A13="",M13=""),N13,0) + IF(AND(A9="",M9="",A10="",M10="",A11="",M11="",A12="",M12="",A13="",M13="",A14="",M14=""),N14,0) + IF(AND(A9="",M9="",A10="",M10="",A11="",M11="",A12="",M12="",A13="",M13="",A14="",M14="",A15="",M15=""),N15,0) + IF(AND(A9="",M9="",A10="",M10="",A11="",M11="",A12="",M12="",A13="",M13="",A14="",M14="",A15="",M15="",A16="",M16=""),N16,0) ) - ( INT( ( (H8="吊飾") + (IF(AND(A9="",M9=""),H9="吊飾",0)) + (IF(AND(A9="",M9="",A10="",M10=""),H10="吊飾",0)) + (IF(AND(A9="",M9="",A10="",M10="",A11="",M11=""),H11="吊飾",0)) + (IF(AND(A9="",M9="",A10="",M10="",A11="",M11="",A12="",M12=""),H12="吊飾",0)) + (IF(AND(A9="",M9="",A10="",M10="",A11="",M11="",A12="",M12="",A13="",M13=""),H13="吊飾",0)) + (IF(AND(A9="",M9="",A10="",M10="",A11="",M11="",A12="",M12="",A13="",M13="",A14="",M14=""),H14="吊飾",0)) + (IF(AND(A9="",M9="",A10="",M10="",A11="",M11="",A12="",M12="",A13="",M13="",A14="",M14="",A15="",M15=""),H15="吊飾",0)) ) / 2 ) * 220 + MAX(0, ( (H8="鎖匙扣") + (IF(AND(A9="",M9=""),H9="鎖匙扣",0)) + (IF(AND(A9="",M9="",A10="",M10=""),H10="鎖匙扣",0)) + (IF(AND(A9="",M9="",A10="",M10="",A11="",M11=""),H11="鎖匙扣",0)) + (IF(AND(A9="",M9="",A10="",M10="",A11="",M11="",A12="",M12=""),H12="鎖匙扣",0)) + (IF(AND(A9="",M9="",A10="",M10="",A11="",M11="",A12="",M12="",A13="",M13=""),H13="鎖匙扣",0)) + (IF(AND(A9="",M9="",A10="",M10="",A11="",M11="",A12="",M12="",A13="",M13="",A14="",M14=""),H14="鎖匙扣",0)) + (IF(AND(A9="",M9="",A10="",M10="",A11="",M11="",A12="",M12="",A13="",M13="",A14="",M14="",A15="",M15=""),H15="鎖匙扣",0)) ) - 1 ) * 20 ), 0 )} -> 474 | P8: =IF(ISNUMBER(M8), M8 - N8 - (O8 + IF(AND(A9="",M9=""),O9,0) + IF(AND(A9="",M9="",A10="",M10=""),O10,0) + IF(AND(A9="",M9="",A10="",M10="",A11="",M11=""),O11,0) + IF(AND(A9="",M9="",A10="",M10="",A11="",M11="",A12="",M12=""),O12,0) + IF(AND(A9="",M9="",A10="",M10="",A11="",M11="",A12="",M12="",A13="",M13=""),O13,0) + IF(AND(A9="",M9="",A10="",M10="",A11="",M11="",A12="",M12="",A13="",M13="",A14="",M14=""),O14,0) + IF(AND(A9="",M9="",A10="",M10="",A11="",M11="",A12="",M12="",A13="",M13="",A14="",M14="",A15="",M15=""),O15,0) + IF(AND(A9="",M9="",A10="",M10="",A11="",M11="",A12="",M12="",A13="",M13="",A14="",M14="",A15="",M15="",A16="",M16=""),O16,0) + IF(AND(A9="",M9="",A10="",M10="",A11="",M11="",A12="",M12="",A13="",M13="",A14="",M14="",A15="",M15="",A16="",M16="",A17="",M17=""),O17,0) ), -N8 - O8 ) -> 1686 | Q8: 2
F9: 嬰兒(P) | G9: 腳 | H9: 鎖匙扣 | I9: 不锈鋼 | J9: 1 | K9: 右腳 | L9: 第32批 | N9: {=IF(鎖售表[[#This Row],[產品]]="鎖匙扣", _xlfn.XLOOKUP(鎖售表[[#This Row],[對象]]&鎖售表[[#This Row],[材料]]&鎖售表[[#This Row],[數量]], 成本表_鎖匙扣!$A$2:$A$100&成本表_鎖匙扣!$C$2:$C$100&成本表_鎖匙扣!$D$2:$D$100, 成本表_鎖匙扣!$E$2:$E$100, 0), _xlfn.XLOOKUP(鎖售表[[#This Row],[對象]]&鎖售表[[#This Row],[產品]]&鎖售表[[#This Row],[材料]]&鎖售表[[#This Row],[數量]], 成本表_吊飾!$A$2:$A$100&成本表_吊飾!$B$2:$B$100&成本表_吊飾!$C$2:$C$100&成本表_吊飾!$D$2:$D$100, 成本表_吊飾!$E$2:$E$100, 0) ) + IF(ISNUMBER(M9), ( IF(AND(A10="",M10=""),N10,0) + IF(AND(A10="",M10="",A11="",M11=""),N11,0) + IF(AND(A10="",M10="",A11="",M11="",A12="",M12=""),N12,0) + IF(AND(A10="",M10="",A11="",M11="",A12="",M12="",A13="",M13=""),N13,0) + IF(AND(A10="",M10="",A11="",M11="",A12="",M12="",A13="",M13="",A14="",M14=""),N14,0) + IF(AND(A10="",M10="",A11="",M11="",A12="",M12="",A13="",M13="",A14="",M14="",A15="",M15=""),N15,0) + IF(AND(A10="",M10="",A11="",M11="",A12="",M12="",A13="",M13="",A14="",M14="",A15="",M15="",A16="",M16=""),N16,0) + IF(AND(A10="",M10="",A11="",M11="",A12="",M12="",A13="",M13="",A14="",M14="",A15="",M15="",A16="",M16="",A17="",M17=""),N17,0) ) - ( INT( ( (H9="吊飾") + (IF(AND(A10="",M10=""),H10="吊飾",0)) + (IF(AND(A10="",M10="",A11="",M11=""),H11="吊飾",0)) + (IF(AND(A10="",M10="",A11="",M11="",A12="",M12=""),H12="吊飾",0)) + (IF(AND(A10="",M10="",A11="",M11="",A12="",M12="",A13="",M13=""),H13="吊飾",0)) + (IF(AND(A10="",M10="",A11="",M11="",A12="",M12="",A13="",M13="",A14="",M14=""),H14="吊飾",0)) + (IF(AND(A10="",M10="",A11="",M11="",A12="",M12="",A13="",M13="",A14="",M14="",A15="",M15=""),H15="吊飾",0)) + (IF(AND(A10="",M10="",A11="",M11="",A12="",M12="",A13="",M13="",A14="",M14="",A15="",M15="",A16="",M16=""),H16="吊飾",0)) ) / 2 ) * 220 + MAX(0, ( (H9="鎖匙扣") + (IF(AND(A10="",M10=""),H10="鎖匙扣",0)) + (IF(AND(A10="",M10="",A11="",M11=""),H11="鎖匙扣",0)) + (IF(AND(A10="",M10="",A11="",M11="",A12="",M12=""),H12="鎖匙扣",0)) + (IF(AND(A10="",M10="",A11="",M11="",A12="",M12="",A13="",M13=""),H13="鎖匙扣",0)) + (IF(AND(A10="",M10="",A11="",M11="",A12="",M12="",A13="",M13="",A14="",M14=""),H14="鎖匙扣",0)) + (IF(AND(A10="",M10="",A11="",M11="",A12="",M12="",A13="",M13="",A14="",M14="",A15="",M15=""),H15="鎖匙扣",0)) + (IF(AND(A10="",M10="",A11="",M11="",A12="",M12="",A13="",M13="",A14="",M14="",A15="",M15="",A16="",M16=""),H16="鎖匙扣",0)) ) - 1 ) * 20 ), 0 )} -> 247 | P9: =IF(ISNUMBER(M9), M9 - N9 - (O9 + IF(AND(A10="",M10=""),O10,0) + IF(AND(A10="",M10="",A11="",M11=""),O11,0) + IF(AND(A10="",M10="",A11="",M11="",A12="",M12=""),O12,0) + IF(AND(A10="",M10="",A11="",M11="",A12="",M12="",A13="",M13=""),O13,0) + IF(AND(A10="",M10="",A11="",M11="",A12="",M12="",A13="",M13="",A14="",M14=""),O14,0) + IF(AND(A10="",M10="",A11="",M11="",A12="",M12="",A13="",M13="",A14="",M14="",A15="",M15=""),O15,0) + IF(AND(A10="",M10="",A11="",M11="",A12="",M12="",A13="",M13="",A14="",M14="",A15="",M15="",A16="",M16=""),O16,0) + IF(AND(A10="",M10="",A11="",M11="",A12="",M12="",A13="",M13="",A14="",M14="",A15="",M15="",A16="",M16="",A17="",M17=""),O17,0) + IF(AND(A10="",M10="",A11="",M11="",A12="",M12="",A13="",M13="",A14="",M14="",A15="",M15="",A16="",M16="",A17="",M17="",A18="",M18=""),O18,0) ), -N9 - O9 ) -> -247 | Q9: 2
A10: 4 | B10: 46046 | C10: Kathleen | D10: ALI | E10: CIA | F10: 嬰兒 | G10: 手 | H10: 鎖匙扣 | I10: 不锈鋼 | J10: 2 | L10: 第32批 | M10: 3980 | N10: {=IF(鎖售表[[#This Row],[產品]]="鎖匙扣", _xlfn.XLOOKUP(鎖售表[[#This Row],[對象]]&鎖售表[[#This Row],[材料]]&鎖售表[[#This Row],[數量]], 成本表_鎖匙扣!$A$2:$A$100&成本表_鎖匙扣!$C$2:$C$100&成本表_鎖匙扣!$D$2:$D$100, 成本表_鎖匙扣!$E$2:$E$100, 0), _xlfn.XLOOKUP(鎖售表[[#This Row],[對象]]&鎖售表[[#This Row],[產品]]&鎖售表[[#This Row],[材料]]&鎖售表[[#This Row],[數量]], 成本表_吊飾!$A$2:$A$100&成本表_吊飾!$B$2:$B$100&成本表_吊飾!$C$2:$C$100&成本表_吊飾!$D$2:$D$100, 成本表_吊飾!$E$2:$E$100, 0) ) + IF(ISNUMBER(M10), ( IF(AND(A11="",M11=""),N11,0) + IF(AND(A11="",M11="",A12="",M12=""),N12,0) + IF(AND(A11="",M11="",A12="",M12="",A13="",M13=""),N13,0) + IF(AND(A11="",M11="",A12="",M12="",A13="",M13="",A14="",M14=""),N14,0) + IF(AND(A11="",M11="",A12="",M12="",A13="",M13="",A14="",M14="",A15="",M15=""),N15,0) + IF(AND(A11="",M11="",A12="",M12="",A13="",M13="",A14="",M14="",A15="",M15="",A16="",M16=""),N16,0) + IF(AND(A11="",M11="",A12="",M12="",A13="",M13="",A14="",M14="",A15="",M15="",A16="",M16="",A17="",M17=""),N17,0) + IF(AND(A11="",M11="",A12="",M12="",A13="",M13="",A14="",M14="",A15="",M15="",A16="",M16="",A17="",M17="",A18="",M18=""),N18,0) ) - ( INT( ( (H10="吊飾") + (IF(AND(A11="",M11=""),H11="吊飾",0)) + (IF(AND(A11="",M11="",A12="",M12=""),H12="吊飾",0)) + (IF(AND(A11="",M11="",A12="",M12="",A13="",M13=""),H13="吊飾",0)) + (IF(AND(A11="",M11="",A12="",M12="",A13="",M13="",A14="",M14=""),H14="吊飾",0)) + (IF(AND(A11="",M11="",A12="",M12="",A13="",M13="",A14="",M14="",A15="",M15=""),H15="吊飾",0)) + (IF(AND(A11="",M11="",A12="",M12="",A13="",M13="",A14="",M14="",A15="",M15="",A16="",M16=""),H16="吊飾",0)) + (IF(AND(A11="",M11="",A12="",M12="",A13="",M13="",A14="",M14="",A15="",M15="",A16="",M16="",A17="",M17=""),H17="吊飾",0)) ) / 2 ) * 220 + MAX(0, ( (H10="鎖匙扣") + (IF(AND(A11="",M11=""),H11="鎖匙扣",0)) + (IF(AND(A11="",M11="",A12="",M12=""),H12="鎖匙扣",0)) + (IF(AND(A11="",M11="",A12="",M12="",A13="",M13=""),H13="鎖匙扣",0)) + (IF(AND(A11="",M11="",A12="",M12="",A13="",M13="",A14="",M14=""),H14="鎖匙扣",0)) + (IF(AND(A11="",M11="",A12="",M12="",A13="",M13="",A14="",M14="",A15="",M15=""),H15="鎖匙扣",0)) + (IF(AND(A11="",M11="",A12="",M12="",A13="",M13="",A14="",M14="",A15="",M15="",A16="",M16=""),H16="鎖匙扣",0)) + (IF(AND(A11="",M11="",A12="",M12="",A13="",M13="",A14="",M14="",A15="",M15="",A16="",M16="",A17="",M17=""),H17="鎖匙扣",0)) ) - 1 ) * 20 ), 0 )} -> 985 | P10: =IF(ISNUMBER(M10), M10 - N10 - (O10 + IF(AND(A11="",M11=""),O11,0) + IF(AND(A11="",M11="",A12="",M12=""),O12,0) + IF(AND(A11="",M11="",A12="",M12="",A13="",M13=""),O13,0) + IF(AND(A11="",M11="",A12="",M12="",A13="",M13="",A14="",M14=""),O14,0) + IF(AND(A11="",M11="",A12="",M12="",A13="",M13="",A14="",M14="",A15="",M15=""),O15,0) + IF(AND(A11="",M11="",A12="",M12="",A13="",M13="",A14="",M14="",A15="",M15="",A16="",M16=""),O16,0) + IF(AND(A11="",M11="",A12="",M12="",A13="",M13="",A14="",M14="",A15="",M15="",A16="",M16="",A17="",M17=""),O17,0) + IF(AND(A11="",M11="",A12="",M12="",A13="",M13="",A14="",M14="",A15="",M15="",A16="",M16="",A17="",M17="",A18="",M18=""),O18,0) + IF(AND(A11="",M11="",A12="",M12="",A13="",M13="",A14="",M14="",A15="",M15="",A16="",M16="",A17="",M17="",A18="",M18="",A19="",M19=""),O19,0) ), -N10 - O10 ) -> 2995 | Q10: 2
D11: ALI | E11: CIA | F11: 嬰兒 | G11: 腳 | H11: 鎖匙扣 | I11: 不锈鋼 | J11: 2 | L11: 第32批 | N11: {=IF(鎖售表[[#This Row],[產品]]="鎖匙扣", _xlfn.XLOOKUP(鎖售表[[#This Row],[對象]]&鎖售表[[#This Row],[材料]]&鎖售表[[#This Row],[數量]], 成本表_鎖匙扣!$A$2:$A$100&成本表_鎖匙扣!$C$2:$C$100&成本表_鎖匙扣!$D$2:$D$100, 成本表_鎖匙扣!$E$2:$E$100, 0), _xlfn.XLOOKUP(鎖售表[[#This Row],[對象]]&鎖售表[[#This Row],[產品]]&鎖售表[[#This Row],[材料]]&鎖售表[[#This Row],[數量]], 成本表_吊飾!$A$2:$A$100&成本表_吊飾!$B$2:$B$100&成本表_吊飾!$C$2:$C$100&成本表_吊飾!$D$2:$D$100, 成本表_吊飾!$E$2:$E$100, 0) ) + IF(ISNUMBER(M11), ( IF(AND(A12="",M12=""),N12,0) + IF(AND(A12="",M12="",A13="",M13=""),N13,0) + IF(AND(A12="",M12="",A13="",M13="",A14="",M14=""),N14,0) + IF(AND(A12="",M12="",A13="",M13="",A14="",M14="",A15="",M15=""),N15,0) + IF(AND(A12="",M12="",A13="",M13="",A14="",M14="",A15="",M15="",A16="",M16=""),N16,0) + IF(AND(A12="",M12="",A13="",M13="",A14="",M14="",A15="",M15="",A16="",M16="",A17="",M17=""),N17,0) + IF(AND(A12="",M12="",A13="",M13="",A14="",M14="",A15="",M15="",A16="",M16="",A17="",M17="",A18="",M18=""),N18,0) + IF(AND(A12="",M12="",A13="",M13="",A14="",M14="",A15="",M15="",A16="",M16="",A17="",M17="",A18="",M18="",A19="",M19=""),N19,0) ) - ( INT( ( (H11="吊飾") + (IF(AND(A12="",M12=""),H12="吊飾",0)) + (IF(AND(A12="",M12="",A13="",M13=""),H13="吊飾",0)) + (IF(AND(A12="",M12="",A13="",M13="",A14="",M14=""),H14="吊飾",0)) + (IF(AND(A12="",M12="",A13="",M13="",A14="",M14="",A15="",M15=""),H15="吊飾",0)) + (IF(AND(A12="",M12="",A13="",M13="",A14="",M14="",A15="",M15="",A16="",M16=""),H16="吊飾",0)) + (IF(AND(A12="",M12="",A13="",M13="",A14="",M14="",A15="",M15="",A16="",M16="",A17="",M17=""),H17="吊飾",0)) + (IF(AND(A12="",M12="",A13="",M13="",A14="",M14="",A15="",M15="",A16="",M16="",A17="",M17="",A18="",M18=""),H18="吊飾",0)) ) / 2 ) * 220 + MAX(0, ( (H11="鎖匙扣") + (IF(AND(A12="",M12=""),H12="鎖匙扣",0)) + (IF(AND(A12="",M12="",A13="",M13=""),H13="鎖匙扣",0)) + (IF(AND(A12="",M12="",A13="",M13="",A14="",M14=""),H14="鎖匙扣",0)) + (IF(AND(A12="",M12="",A13="",M13="",A14="",M14="",A15="",M15=""),H15="鎖匙扣",0)) + (IF(AND(A12="",M12="",A13="",M13="",A14="",M14="",A15="",M15="",A16="",M16=""),H16="鎖匙扣",0)) + (IF(AND(A12="",M12="",A13="",M13="",A14="",M14="",A15="",M15="",A16="",M16="",A17="",M17=""),H17="鎖匙扣",0)) + (IF(AND(A12="",M12="",A13="",M13="",A14="",M14="",A15="",M15="",A16="",M16="",A17="",M17="",A18="",M18=""),H18="鎖匙扣",0)) ) - 1 ) * 20 ), 0 )} -> 290 | P11: =IF(ISNUMBER(M11), M11 - N11 - (O11 + IF(AND(A12="",M12=""),O12,0) + IF(AND(A12="",M12="",A13="",M13=""),O13,0) + IF(AND(A12="",M12="",A13="",M13="",A14="",M14=""),O14,0) + IF(AND(A12="",M12="",A13="",M13="",A14="",M14="",A15="",M15=""),O15,0) + IF(AND(A12="",M12="",A13="",M13="",A14="",M14="",A15="",M15="",A16="",M16=""),O16,0) + IF(AND(A12="",M12="",A13="",M13="",A14="",M14="",A15="",M15="",A16="",M16="",A17="",M17=""),O17,0) + IF(AND(A12="",M12="",A13="",M13="",A14="",M14="",A15="",M15="",A16="",M16="",A17="",M17="",A18="",M18=""),O18,0) + IF(AND(A12="",M12="",A13="",M13="",A14="",M14="",A15="",M15="",A16="",M16="",A17="",M17="",A18="",M18="",A19="",M19=""),O19,0) + IF(AND(A12="",M12="",A13="",M13="",A14="",M14="",A15="",M15="",A16="",M16="",A17="",M17="",A18="",M18="",A19="",M19="",A20="",M20=""),O20,0) ), -N11 - O11 ) -> -290 | Q11: 2
D12: A | E12: // | F12: 嬰兒 | G12: 腳 | H12: 吊飾 | I12: 925銀 | J12: 1 | L12: 第32批 | N12: {=IF(鎖售表[[#This Row],[產品]]="鎖匙扣", _xlfn.XLOOKUP(鎖售表[[#This Row],[對象]]&鎖售表[[#This Row],[材料]]&鎖售表[[#This Row],[數量]], 成本表_鎖匙扣!$A$2:$A$100&成本表_鎖匙扣!$C$2:$C$100&成本表_鎖匙扣!$D$2:$D$100, 成本表_鎖匙扣!$E$2:$E$100, 0), _xlfn.XLOOKUP(鎖售表[[#This Row],[對象]]&鎖售表[[#This Row],[產品]]&鎖售表[[#This Row],[材料]]&鎖售表[[#This Row],[數量]], 成本表_吊飾!$A$2:$A$100&成本表_吊飾!$B$2:$B$100&成本表_吊飾!$C$2:$C$100&成本表_吊飾!$D$2:$D$100, 成本表_吊飾!$E$2:$E$100, 0) ) + IF(ISNUMBER(M12), ( IF(AND(A13="",M13=""),N13,0) + IF(AND(A13="",M13="",A14="",M14=""),N14,0) + IF(AND(A13="",M13="",A14="",M14="",A15="",M15=""),N15,0) + IF(AND(A13="",M13="",A14="",M14="",A15="",M15="",A16="",M16=""),N16,0) + IF(AND(A13="",M13="",A14="",M14="",A15="",M15="",A16="",M16="",A17="",M17=""),N17,0) + IF(AND(A13="",M13="",A14="",M14="",A15="",M15="",A16="",M16="",A17="",M17="",A18="",M18=""),N18,0) + IF(AND(A13="",M13="",A14="",M14="",A15="",M15="",A16="",M16="",A17="",M17="",A18="",M18="",A19="",M19=""),N19,0) + IF(AND(A13="",M13="",A14="",M14="",A15="",M15="",A16="",M16="",A17="",M17="",A18="",M18="",A19="",M19="",A20="",M20=""),N20,0) ) - ( INT( ( (H12="吊飾") + (IF(AND(A13="",M13=""),H13="吊飾",0)) + (IF(AND(A13="",M13="",A14="",M14=""),H14="吊飾",0)) + (IF(AND(A13="",M13="",A14="",M14="",A15="",M15=""),H15="吊飾",0)) + (IF(AND(A13="",M13="",A14="",M14="",A15="",M15="",A16="",M16=""),H16="吊飾",0)) + (IF(AND(A13="",M13="",A14="",M14="",A15="",M15="",A16="",M16="",A17="",M17=""),H17="吊飾",0)) + (IF(AND(A13="",M13="",A14="",M14="",A15="",M15="",A16="",M16="",A17="",M17="",A18="",M18=""),H18="吊飾",0)) + (IF(AND(A13="",M13="",A14="",M14="",A15="",M15="",A16="",M16="",A17="",M17="",A18="",M18="",A19="",M19=""),H19="吊飾",0)) ) / 2 ) * 220 + MAX(0, ( (H12="鎖匙扣") + (IF(AND(A13="",M13=""),H13="鎖匙扣",0)) + (IF(AND(A13="",M13="",A14="",M14=""),H14="鎖匙扣",0)) + (IF(AND(A13="",M13="",A14="",M14="",A15="",M15=""),H15="鎖匙扣",0)) + (IF(AND(A13="",M13="",A14="",M14="",A15="",M15="",A16="",M16=""),H16="鎖匙扣",0)) + (IF(AND(A13="",M13="",A14="",M14="",A15="",M15="",A16="",M16="",A17="",M17=""),H17="鎖匙扣",0)) + (IF(AND(A13="",M13="",A14="",M14="",A15="",M15="",A16="",M16="",A17="",M17="",A18="",M18=""),H18="鎖匙扣",0)) + (IF(AND(A13="",M13="",A14="",M14="",A15="",M15="",A16="",M16="",A17="",M17="",A18="",M18="",A19="",M19=""),H19="鎖匙扣",0)) ) - 1 ) * 20 ), 0 )} -> 425 | P12: =IF(ISNUMBER(M12), M12 - N12 - (O12 + IF(AND(A13="",M13=""),O13,0) + IF(AND(A13="",M13="",A14="",M14=""),O14,0) + IF(AND(A13="",M13="",A14="",M14="",A15="",M15=""),O15,0) + IF(AND(A13="",M13="",A14="",M14="",A15="",M15="",A16="",M16=""),O16,0) + IF(AND(A13="",M13="",A14="",M14="",A15="",M15="",A16="",M16="",A17="",M17=""),O17,0) + IF(AND(A13="",M13="",A14="",M14="",A15="",M15="",A16="",M16="",A17="",M17="",A18="",M18=""),O18,0) + IF(AND(A13="",M13="",A14="",M14="",A15="",M15="",A16="",M16="",A17="",M17="",A18="",M18="",A19="",M19=""),O19,0) + IF(AND(A13="",M13="",A14="",M14="",A15="",M15="",A16="",M16="",A17="",M17="",A18="",M18="",A19="",M19="",A20="",M20=""),O20,0) + IF(AND(A13="",M13="",A14="",M14="",A15="",M15="",A16="",M16="",A17="",M17="",A18="",M18="",A19="",M19="",A20="",M20="",A21="",M21=""),O21,0) ), -N12 - O12 ) -> -425 | Q12: 2
A13: 5 | B13: 46049 | C13: Gaeac | D13: ? | E13: ? | F13: 嬰兒 | G13: 手 | H13: 鎖匙扣 | I13: 不锈鋼 | J13: 2 | L13: 第32批 | M13: 2400 | N13: {=IF(鎖售表[[#This Row],[產品]]="鎖匙扣", _xlfn.XLOOKUP(鎖售表[[#This Row],[對象]]&鎖售表[[#This Row],[材料]]&鎖售表[[#This Row],[數量]], 成本表_鎖匙扣!$A$2:$A$100&成本表_鎖匙扣!$C$2:$C$100&成本表_鎖匙扣!$D$2:$D$100, 成本表_鎖匙扣!$E$2:$E$100, 0), _xlfn.XLOOKUP(鎖售表[[#This Row],[對象]]&鎖售表[[#This Row],[產品]]&鎖售表[[#This Row],[材料]]&鎖售表[[#This Row],[數量]], 成本表_吊飾!$A$2:$A$100&成本表_吊飾!$B$2:$B$100&成本表_吊飾!$C$2:$C$100&成本表_吊飾!$D$2:$D$100, 成本表_吊飾!$E$2:$E$100, 0) ) + IF(ISNUMBER(M13), ( IF(AND(A14="",M14=""),N14,0) + IF(AND(A14="",M14="",A15="",M15=""),N15,0) + IF(AND(A14="",M14="",A15="",M15="",A16="",M16=""),N16,0) + IF(AND(A14="",M14="",A15="",M15="",A16="",M16="",A17="",M17=""),N17,0) + IF(AND(A14="",M14="",A15="",M15="",A16="",M16="",A17="",M17="",A18="",M18=""),N18,0) + IF(AND(A14="",M14="",A15="",M15="",A16="",M16="",A17="",M17="",A18="",M18="",A19="",M19=""),N19,0) + IF(AND(A14="",M14="",A15="",M15="",A16="",M16="",A17="",M17="",A18="",M18="",A19="",M19="",A20="",M20=""),N20,0) + IF(AND(A14="",M14="",A15="",M15="",A16="",M16="",A17="",M17="",A18="",M18="",A19="",M19="",A20="",M20="",A21="",M21=""),N21,0) ) - ( INT( ( (H13="吊飾") + (IF(AND(A14="",M14=""),H14="吊飾",0)) + (IF(AND(A14="",M14="",A15="",M15=""),H15="吊飾",0)) + (IF(AND(A14="",M14="",A15="",M15="",A16="",M16=""),H16="吊飾",0)) + (IF(AND(A14="",M14="",A15="",M15="",A16="",M16="",A17="",M17=""),H17="吊飾",0)) + (IF(AND(A14="",M14="",A15="",M15="",A16="",M16="",A17="",M17="",A18="",M18=""),H18="吊飾",0)) + (IF(AND(A14="",M14="",A15="",M15="",A16="",M16="",A17="",M17="",A18="",M18="",A19="",M19=""),H19="吊飾",0)) + (IF(AND(A14="",M14="",A15="",M15="",A16="",M16="",A17="",M17="",A18="",M18="",A19="",M19="",A20="",M20=""),H20="吊飾",0)) ) / 2 ) * 220 + MAX(0, ( (H13="鎖匙扣") + (IF(AND(A14="",M14=""),H14="鎖匙扣",0)) + (IF(AND(A14="",M14="",A15="",M15=""),H15="鎖匙扣",0)) + (IF(AND(A14="",M14="",A15="",M15="",A16="",M16=""),H16="鎖匙扣",0)) + (IF(AND(A14="",M14="",A15="",M15="",A16="",M16="",A17="",M17=""),H17="鎖匙扣",0)) + (IF(AND(A14="",M14="",A15="",M15="",A16="",M16="",A17="",M17="",A18="",M18=""),H18="鎖匙扣",0)) + (IF(AND(A14="",M14="",A15="",M15="",A16="",M16="",A17="",M17="",A18="",M18="",A19="",M19=""),H19="鎖匙扣",0)) + (IF(AND(A14="",M14="",A15="",M15="",A16="",M16="",A17="",M17="",A18="",M18="",A19="",M19="",A20="",M20=""),H20="鎖匙扣",0)) ) - 1 ) * 20 ), 0 )} -> 560 | P13: =IF(ISNUMBER(M13), M13 - N13 - (O13 + IF(AND(A14="",M14=""),O14,0) + IF(AND(A14="",M14="",A15="",M15=""),O15,0) + IF(AND(A14="",M14="",A15="",M15="",A16="",M16=""),O16,0) + IF(AND(A14="",M14="",A15="",M15="",A16="",M16="",A17="",M17=""),O17,0) + IF(AND(A14="",M14="",A15="",M15="",A16="",M16="",A17="",M17="",A18="",M18=""),O18,0) + IF(AND(A14="",M14="",A15="",M15="",A16="",M16="",A17="",M17="",A18="",M18="",A19="",M19=""),O19,0) + IF(AND(A14="",M14="",A15="",M15="",A16="",M16="",A17="",M17="",A18="",M18="",A19="",M19="",A20="",M20=""),O20,0) + IF(AND(A14="",M14="",A15="",M15="",A16="",M16="",A17="",M17="",A18="",M18="",A19="",M19="",A20="",M20="",A21="",M21=""),O21,0) + IF(AND(A14="",M14="",A15="",M15="",A16="",M16="",A17="",M17="",A18="",M18="",A19="",M19="",A20="",M20="",A21="",M21="",A22="",M22=""),O22,0) ), -N13 - O13 ) -> 1840 | Q13: 0
D14: ? | E14: ? | F14: 嬰兒 | G14: 腳 | H14: 鎖匙扣 | I14: 不锈鋼 | J14: 2 | L14: 第32批 | N14: {=IF(鎖售表[[#This Row],[產品]]="鎖匙扣", _xlfn.XLOOKUP(鎖售表[[#This Row],[對象]]&鎖售表[[#This Row],[材料]]&鎖售表[[#This Row],[數量]], 成本表_鎖匙扣!$A$2:$A$100&成本表_鎖匙扣!$C$2:$C$100&成本表_鎖匙扣!$D$2:$D$100, 成本表_鎖匙扣!$E$2:$E$100, 0), _xlfn.XLOOKUP(鎖售表[[#This Row],[對象]]&鎖售表[[#This Row],[產品]]&鎖售表[[#This Row],[材料]]&鎖售表[[#This Row],[數量]], 成本表_吊飾!$A$2:$A$100&成本表_吊飾!$B$2:$B$100&成本表_吊飾!$C$2:$C$100&成本表_吊飾!$D$2:$D$100, 成本表_吊飾!$E$2:$E$100, 0) ) + IF(ISNUMBER(M14), ( IF(AND(A15="",M15=""),N15,0) + IF(AND(A15="",M15="",A16="",M16=""),N16,0) + IF(AND(A15="",M15="",A16="",M16="",A17="",M17=""),N17,0) + IF(AND(A15="",M15="",A16="",M16="",A17="",M17="",A18="",M18=""),N18,0) + IF(AND(A15="",M15="",A16="",M16="",A17="",M17="",A18="",M18="",A19="",M19=""),N19,0) + IF(AND(A15="",M15="",A16="",M16="",A17="",M17="",A18="",M18="",A19="",M19="",A20="",M20=""),N20,0) + IF(AND(A15="",M15="",A16="",M16="",A17="",M17="",A18="",M18="",A19="",M19="",A20="",M20="",A21="",M21=""),N21,0) + IF(AND(A15="",M15="",A16="",M16="",A17="",M17="",A18="",M18="",A19="",M19="",A20="",M20="",A21="",M21="",A22="",M22=""),N22,0) ) - ( INT( ( (H14="吊飾") + (IF(AND(A15="",M15=""),H15="吊飾",0)) + (IF(AND(A15="",M15="",A16="",M16=""),H16="吊飾",0)) + (IF(AND(A15="",M15="",A16="",M16="",A17="",M17=""),H17="吊飾",0)) + (IF(AND(A15="",M15="",A16="",M16="",A17="",M17="",A18="",M18=""),H18="吊飾",0)) + (IF(AND(A15="",M15="",A16="",M16="",A17="",M17="",A18="",M18="",A19="",M19=""),H19="吊飾",0)) + (IF(AND(A15="",M15="",A16="",M16="",A17="",M17="",A18="",M18="",A19="",M19="",A20="",M20=""),H20="吊飾",0)) + (IF(AND(A15="",M15="",A16="",M16="",A17="",M17="",A18="",M18="",A19="",M19="",A20="",M20="",A21="",M21=""),H21="吊飾",0)) ) / 2 ) * 220 + MAX(0, ( (H14="鎖匙扣") + (IF(AND(A15="",M15=""),H15="鎖匙扣",0)) + (IF(AND(A15="",M15="",A16="",M16=""),H16="鎖匙扣",0)) + (IF(AND(A15="",M15="",A16="",M16="",A17="",M17=""),H17="鎖匙扣",0)) + (IF(AND(A15="",M15="",A16="",M16="",A17="",M17="",A18="",M18=""),H18="鎖匙扣",0)) + (IF(AND(A15="",M15="",A16="",M16="",A17="",M17="",A18="",M18="",A19="",M19=""),H19="鎖匙扣",0)) + (IF(AND(A15="",M15="",A16="",M16="",A17="",M17="",A18="",M18="",A19="",M19="",A20="",M20=""),H20="鎖匙扣",0)) + (IF(AND(A15="",M15="",A16="",M16="",A17="",M17="",A18="",M18="",A19="",M19="",A20="",M20="",A21="",M21=""),H21="鎖匙扣",0)) ) - 1 ) * 20 ), 0 )} -> 290 | P14: =IF(ISNUMBER(M14), M14 - N14 - (O14 + IF(AND(A15="",M15=""),O15,0) + IF(AND(A15="",M15="",A16="",M16=""),O16,0) + IF(AND(A15="",M15="",A16="",M16="",A17="",M17=""),O17,0) + IF(AND(A15="",M15="",A16="",M16="",A17="",M17="",A18="",M18=""),O18,0) + IF(AND(A15="",M15="",A16="",M16="",A17="",M17="",A18="",M18="",A19="",M19=""),O19,0) + IF(AND(A15="",M15="",A16="",M16="",A17="",M17="",A18="",M18="",A19="",M19="",A20="",M20=""),O20,0) + IF(AND(A15="",M15="",A16="",M16="",A17="",M17="",A18="",M18="",A19="",M19="",A20="",M20="",A21="",M21=""),O21,0) + IF(AND(A15="",M15="",A16="",M16="",A17="",M17="",A18="",M18="",A19="",M19="",A20="",M20="",A21="",M21="",A22="",M22=""),O22,0) + IF(AND(A15="",M15="",A16="",M16="",A17="",M17="",A18="",M18="",A19="",M19="",A20="",M20="",A21="",M21="",A22="",M22="",A23="",M23=""),O23,0) ), -N14 - O14 ) -> -290 | Q14: 0
A15: 6 | B15: 46047 | C15: SalinaLai | D15: Lucia | E15: 1117 | F15: 嬰兒(P) | G15: 手 | H15: 鎖匙扣 | I15: 不锈鋼 | J15: 1 | K15: 左手 | L15: 第32批 | M15: 4940 | N15: {=IF(鎖售表[[#This Row],[產品]]="鎖匙扣", _xlfn.XLOOKUP(鎖售表[[#This Row],[對象]]&鎖售表[[#This Row],[材料]]&鎖售表[[#This Row],[數量]], 成本表_鎖匙扣!$A$2:$A$100&成本表_鎖匙扣!$C$2:$C$100&成本表_鎖匙扣!$D$2:$D$100, 成本表_鎖匙扣!$E$2:$E$100, 0), _xlfn.XLOOKUP(鎖售表[[#This Row],[對象]]&鎖售表[[#This Row],[產品]]&鎖售表[[#This Row],[材料]]&鎖售表[[#This Row],[數量]], 成本表_吊飾!$A$2:$A$100&成本表_吊飾!$B$2:$B$100&成本表_吊飾!$C$2:$C$100&成本表_吊飾!$D$2:$D$100, 成本表_吊飾!$E$2:$E$100, 0) ) + IF(ISNUMBER(M15), ( IF(AND(A16="",M16=""),N16,0) + IF(AND(A16="",M16="",A17="",M17=""),N17,0) + IF(AND(A16="",M16="",A17="",M17="",A18="",M18=""),N18,0) + IF(AND(A16="",M16="",A17="",M17="",A18="",M18="",A19="",M19=""),N19,0) + IF(AND(A16="",M16="",A17="",M17="",A18="",M18="",A19="",M19="",A20="",M20=""),N20,0) + IF(AND(A16="",M16="",A17="",M17="",A18="",M18="",A19="",M19="",A20="",M20="",A21="",M21=""),N21,0) + IF(AND(A16="",M16="",A17="",M17="",A18="",M18="",A19="",M19="",A20="",M20="",A21="",M21="",A22="",M22=""),N22,0) + IF(AND(A16="",M16="",A17="",M17="",A18="",M18="",A19="",M19="",A20="",M20="",A21="",M21="",A22="",M22="",A23="",M23=""),N23,0) ) - ( INT( ( (H15="吊飾") + (IF(AND(A16="",M16=""),H16="吊飾",0)) + (IF(AND(A16="",M16="",A17="",M17=""),H17="吊飾",0)) + (IF(AND(A16="",M16="",A17="",M17="",A18="",M18=""),H18="吊飾",0)) + (IF(AND(A16="",M16="",A17="",M17="",A18="",M18="",A19="",M19=""),H19="吊飾",0)) + (IF(AND(A16="",M16="",A17="",M17="",A18="",M18="",A19="",M19="",A20="",M20=""),H20="吊飾",0)) + (IF(AND(A16="",M16="",A17="",M17="",A18="",M18="",A19="",M19="",A20="",M20="",A21="",M21=""),H21="吊飾",0)) + (IF(AND(A16="",M16="",A17="",M17="",A18="",M18="",A19="",M19="",A20="",M20="",A21="",M21="",A22="",M22=""),H22="吊飾",0)) ) / 2 ) * 220 + MAX(0, ( (H15="鎖匙扣") + (IF(AND(A16="",M16=""),H16="鎖匙扣",0)) + (IF(AND(A16="",M16="",A17="",M17=""),H17="鎖匙扣",0)) + (IF(AND(A16="",M16="",A17="",M17="",A18="",M18=""),H18="鎖匙扣",0)) + (IF(AND(A16="",M16="",A17="",M17="",A18="",M18="",A19="",M19=""),H19="鎖匙扣",0)) + (IF(AND(A16="",M16="",A17="",M17="",A18="",M18="",A19="",M19="",A20="",M20=""),H20="鎖匙扣",0)) + (IF(AND(A16="",M16="",A17="",M17="",A18="",M18="",A19="",M19="",A20="",M20="",A21="",M21=""),H21="鎖匙扣",0)) + (IF(AND(A16="",M16="",A17="",M17="",A18="",M18="",A19="",M19="",A20="",M20="",A21="",M21="",A22="",M22=""),H22="鎖匙扣",0)) ) - 1 ) * 20 ), 0 )} -> 1228 | P15: =IF(ISNUMBER(M15), M15 - N15 - (O15 + IF(AND(A16="",M16=""),O16,0) + IF(AND(A16="",M16="",A17="",M17=""),O17,0) + IF(AND(A16="",M16="",A17="",M17="",A18="",M18=""),O18,0) + IF(AND(A16="",M16="",A17="",M17="",A18="",M18="",A19="",M19=""),O19,0) + IF(AND(A16="",M16="",A17="",M17="",A18="",M18="",A19="",M19="",A20="",M20=""),O20,0) + IF(AND(A16="",M16="",A17="",M17="",A18="",M18="",A19="",M19="",A20="",M20="",A21="",M21=""),O21,0) + IF(AND(A16="",M16="",A17="",M17="",A18="",M18="",A19="",M19="",A20="",M20="",A21="",M21="",A22="",M22=""),O22,0) + IF(AND(A16="",M16="",A17="",M17="",A18="",M18="",A19="",M19="",A20="",M20="",A21="",M21="",A22="",M22="",A23="",M23=""),O23,0) + IF(AND(A16="",M16="",A17="",M17="",A18="",M18="",A19="",M19="",A20="",M20="",A21="",M21="",A22="",M22="",A23="",M23="",A24="",M24=""),O24,0) ), -N15 - O15 ) -> 3712 | Q15: 1
D16: Lucia | E16: 1117 | F16: 嬰兒(P) | G16: 腳 | H16: 鎖匙扣 | I16: 不锈鋼 | J16: 1 | K16: 左腳 | L16: 第32批 | N16: {=IF(鎖售表[[#This Row],[產品]]="鎖匙扣", _xlfn.XLOOKUP(鎖售表[[#This Row],[對象]]&鎖售表[[#This Row],[材料]]&鎖售表[[#This Row],[數量]], 成本表_鎖匙扣!$A$2:$A$100&成本表_鎖匙扣!$C$2:$C$100&成本表_鎖匙扣!$D$2:$D$100, 成本表_鎖匙扣!$E$2:$E$100, 0), _xlfn.XLOOKUP(鎖售表[[#This Row],[對象]]&鎖售表[[#This Row],[產品]]&鎖售表[[#This Row],[材料]]&鎖售表[[#This Row],[數量]], 成本表_吊飾!$A$2:$A$100&成本表_吊飾!$B$2:$B$100&成本表_吊飾!$C$2:$C$100&成本表_吊飾!$D$2:$D$100, 成本表_吊飾!$E$2:$E$100, 0) ) + IF(ISNUMBER(M16), ( IF(AND(A17="",M17=""),N17,0) + IF(AND(A17="",M17="",A18="",M18=""),N18,0) + IF(AND(A17="",M17="",A18="",M18="",A19="",M19=""),N19,0) + IF(AND(A17="",M17="",A18="",M18="",A19="",M19="",A20="",M20=""),N20,0) + IF(AND(A17="",M17="",A18="",M18="",A19="",M19="",A20="",M20="",A21="",M21=""),N21,0) + IF(AND(A17="",M17="",A18="",M18="",A19="",M19="",A20="",M20="",A21="",M21="",A22="",M22=""),N22,0) + IF(AND(A17="",M17="",A18="",M18="",A19="",M19="",A20="",M20="",A21="",M21="",A22="",M22="",A23="",M23=""),N23,0) + IF(AND(A17="",M17="",A18="",M18="",A19="",M19="",A20="",M20="",A21="",M21="",A22="",M22="",A23="",M23="",A24="",M24=""),N24,0) ) - ( INT( ( (H16="吊飾") + (IF(AND(A17="",M17=""),H17="吊飾",0)) + (IF(AND(A17="",M17="",A18="",M18=""),H18="吊飾",0)) + (IF(AND(A17="",M17="",A18="",M18="",A19="",M19=""),H19="吊飾",0)) + (IF(AND(A17="",M17="",A18="",M18="",A19="",M19="",A20="",M20=""),H20="吊飾",0)) + (IF(AND(A17="",M17="",A18="",M18="",A19="",M19="",A20="",M20="",A21="",M21=""),H21="吊飾",0)) + (IF(AND(A17="",M17="",A18="",M18="",A19="",M19="",A20="",M20="",A21="",M21="",A22="",M22=""),H22="吊飾",0)) + (IF(AND(A17="",M17="",A18="",M18="",A19="",M19="",A20="",M20="",A21="",M21="",A22="",M22="",A23="",M23=""),H23="吊飾",0)) ) / 2 ) * 220 + MAX(0, ( (H16="鎖匙扣") + (IF(AND(A17="",M17=""),H17="鎖匙扣",0)) + (IF(AND(A17="",M17="",A18="",M18=""),H18="鎖匙扣",0)) + (IF(AND(A17="",M17="",A18="",M18="",A19="",M19=""),H19="鎖匙扣",0)) + (IF(AND(A17="",M17="",A18="",M18="",A19="",M19="",A20="",M20=""),H20="鎖匙扣",0)) + (IF(AND(A17="",M17="",A18="",M18="",A19="",M19="",A20="",M20="",A21="",M21=""),H21="鎖匙扣",0)) + (IF(AND(A17="",M17="",A18="",M18="",A19="",M19="",A20="",M20="",A21="",M21="",A22="",M22=""),H22="鎖匙扣",0)) + (IF(AND(A17="",M17="",A18="",M18="",A19="",M19="",A20="",M20="",A21="",M21="",A22="",M22="",A23="",M23=""),H23="鎖匙扣",0)) ) - 1 ) * 20 ), 0 )} -> 247 | P16: =IF(ISNUMBER(M16), M16 - N16 - (O16 + IF(AND(A17="",M17=""),O17,0) + IF(AND(A17="",M17="",A18="",M18=""),O18,0) + IF(AND(A17="",M17="",A18="",M18="",A19="",M19=""),O19,0) + IF(AND(A17="",M17="",A18="",M18="",A19="",M19="",A20="",M20=""),O20,0) + IF(AND(A17="",M17="",A18="",M18="",A19="",M19="",A20="",M20="",A21="",M21=""),O21,0) + IF(AND(A17="",M17="",A18="",M18="",A19="",M19="",A20="",M20="",A21="",M21="",A22="",M22=""),O22,0) + IF(AND(A17="",M17="",A18="",M18="",A19="",M19="",A20="",M20="",A21="",M21="",A22="",M22="",A23="",M23=""),O23,0) + IF(AND(A17="",M17="",A18="",M18="",A19="",M19="",A20="",M20="",A21="",M21="",A22="",M22="",A23="",M23="",A24="",M24=""),O24,0) + IF(AND(A17="",M17="",A18="",M18="",A19="",M19="",A20="",M20="",A21="",M21="",A22="",M22="",A23="",M23="",A24="",M24="",A25="",M25=""),O25,0) ), -N16 - O16 ) -> -247 | Q16: 1
D17: // | E17: // | F17: 嬰兒(P) | G17: 手 | H17: 吊飾 | I17: 925銀 | J17: 1 | K17: 左手 | L17: 第32批 | N17: {=IF(鎖售表[[#This Row],[產品]]="鎖匙扣", _xlfn.XLOOKUP(鎖售表[[#This Row],[對象]]&鎖售表[[#This Row],[材料]]&鎖售表[[#This Row],[數量]], 成本表_鎖匙扣!$A$2:$A$100&成本表_鎖匙扣!$C$2:$C$100&成本表_鎖匙扣!$D$2:$D$100, 成本表_鎖匙扣!$E$2:$E$100, 0), _xlfn.XLOOKUP(鎖售表[[#This Row],[對象]]&鎖售表[[#This Row],[產品]]&鎖售表[[#This Row],[材料]]&鎖售表[[#This Row],[數量]], 成本表_吊飾!$A$2:$A$100&成本表_吊飾!$B$2:$B$100&成本表_吊飾!$C$2:$C$100&成本表_吊飾!$D$2:$D$100, 成本表_吊飾!$E$2:$E$100, 0) ) + IF(ISNUMBER(M17), ( IF(AND(A18="",M18=""),N18,0) + IF(AND(A18="",M18="",A19="",M19=""),N19,0) + IF(AND(A18="",M18="",A19="",M19="",A20="",M20=""),N20,0) + IF(AND(A18="",M18="",A19="",M19="",A20="",M20="",A21="",M21=""),N21,0) + IF(AND(A18="",M18="",A19="",M19="",A20="",M20="",A21="",M21="",A22="",M22=""),N22,0) + IF(AND(A18="",M18="",A19="",M19="",A20="",M20="",A21="",M21="",A22="",M22="",A23="",M23=""),N23,0) + IF(AND(A18="",M18="",A19="",M19="",A20="",M20="",A21="",M21="",A22="",M22="",A23="",M23="",A24="",M24=""),N24,0) + IF(AND(A18="",M18="",A19="",M19="",A20="",M20="",A21="",M21="",A22="",M22="",A23="",M23="",A24="",M24="",A25="",M25=""),N25,0) ) - ( INT( ( (H17="吊飾") + (IF(AND(A18="",M18=""),H18="吊飾",0)) + (IF(AND(A18="",M18="",A19="",M19=""),H19="吊飾",0)) + (IF(AND(A18="",M18="",A19="",M19="",A20="",M20=""),H20="吊飾",0)) + (IF(AND(A18="",M18="",A19="",M19="",A20="",M20="",A21="",M21=""),H21="吊飾",0)) + (IF(AND(A18="",M18="",A19="",M19="",A20="",M20="",A21="",M21="",A22="",M22=""),H22="吊飾",0)) + (IF(AND(A18="",M18="",A19="",M19="",A20="",M20="",A21="",M21="",A22="",M22="",A23="",M23=""),H23="吊飾",0)) + (IF(AND(A18="",M18="",A19="",M19="",A20="",M20="",A21="",M21="",A22="",M22="",A23="",M23="",A24="",M24=""),H24="吊飾",0)) ) / 2 ) * 220 + MAX(0, ( (H17="鎖匙扣") + (IF(AND(A18="",M18=""),H18="鎖匙扣",0)) + (IF(AND(A18="",M18="",A19="",M19=""),H19="鎖匙扣",0)) + (IF(AND(A18="",M18="",A19="",M19="",A20="",M20=""),H20="鎖匙扣",0)) + (IF(AND(A18="",M18="",A19="",M19="",A20="",M20="",A21="",M21=""),H21="鎖匙扣",0)) + (IF(AND(A18="",M18="",A19="",M19="",A20="",M20="",A21="",M21="",A22="",M22=""),H22="鎖匙扣",0)) + (IF(AND(A18="",M18="",A19="",M19="",A20="",M20="",A21="",M21="",A22="",M22="",A23="",M23=""),H23="鎖匙扣",0)) + (IF(AND(A18="",M18="",A19="",M19="",A20="",M20="",A21="",M21="",A22="",M22="",A23="",M23="",A24="",M24=""),H24="鎖匙扣",0)) ) - 1 ) * 20 ), 0 )} -> 487 | P17: =IF(ISNUMBER(M17), M17 - N17 - (O17 + IF(AND(A18="",M18=""),O18,0) + IF(AND(A18="",M18="",A19="",M19=""),O19,0) + IF(AND(A18="",M18="",A19="",M19="",A20="",M20=""),O20,0) + IF(AND(A18="",M18="",A19="",M19="",A20="",M20="",A21="",M21=""),O21,0) + IF(AND(A18="",M18="",A19="",M19="",A20="",M20="",A21="",M21="",A22="",M22=""),O22,0) + IF(AND(A18="",M18="",A19="",M19="",A20="",M20="",A21="",M21="",A22="",M22="",A23="",M23=""),O23,0) + IF(AND(A18="",M18="",A19="",M19="",A20="",M20="",A21="",M21="",A22="",M22="",A23="",M23="",A24="",M24=""),O24,0) + IF(AND(A18="",M18="",A19="",M19="",A20="",M20="",A21="",M21="",A22="",M22="",A23="",M23="",A24="",M24="",A25="",M25=""),O25,0) + IF(AND(A18="",M18="",A19="",M19="",A20="",M20="",A21="",M21="",A22="",M22="",A23="",M23="",A24="",M24="",A25="",M25="",A26="",M26=""),O26,0) ), -N17 - O17 ) -> -487 | Q17: 1
D18: ? | E18: // | F18: 嬰兒(P) | G18: 腳 | H18: 吊飾 | I18: 925銀 | J18: 1 | K18: 左腳 | L18: 第32批 | N18: {=IF(鎖售表[[#This Row],[產品]]="鎖匙扣", _xlfn.XLOOKUP(鎖售表[[#This Row],[對象]]&鎖售表[[#This Row],[材料]]&鎖售表[[#This Row],[數量]], 成本表_鎖匙扣!$A$2:$A$100&成本表_鎖匙扣!$C$2:$C$100&成本表_鎖匙扣!$D$2:$D$100, 成本表_鎖匙扣!$E$2:$E$100, 0), _xlfn.XLOOKUP(鎖售表[[#This Row],[對象]]&鎖售表[[#This Row],[產品]]&鎖售表[[#This Row],[材料]]&鎖售表[[#This Row],[數量]], 成本表_吊飾!$A$2:$A$100&成本表_吊飾!$B$2:$B$100&成本表_吊飾!$C$2:$C$100&成本表_吊飾!$D$2:$D$100, 成本表_吊飾!$E$2:$E$100, 0) ) + IF(ISNUMBER(M18), ( IF(AND(A19="",M19=""),N19,0) + IF(AND(A19="",M19="",A20="",M20=""),N20,0) + IF(AND(A19="",M19="",A20="",M20="",A21="",M21=""),N21,0) + IF(AND(A19="",M19="",A20="",M20="",A21="",M21="",A22="",M22=""),N22,0) + IF(AND(A19="",M19="",A20="",M20="",A21="",M21="",A22="",M22="",A23="",M23=""),N23,0) + IF(AND(A19="",M19="",A20="",M20="",A21="",M21="",A22="",M22="",A23="",M23="",A24="",M24=""),N24,0) + IF(AND(A19="",M19="",A20="",M20="",A21="",M21="",A22="",M22="",A23="",M23="",A24="",M24="",A25="",M25=""),N25,0) + IF(AND(A19="",M19="",A20="",M20="",A21="",M21="",A22="",M22="",A23="",M23="",A24="",M24="",A25="",M25="",A26="",M26=""),N26,0) ) - ( INT( ( (H18="吊飾") + (IF(AND(A19="",M19=""),H19="吊飾",0)) + (IF(AND(A19="",M19="",A20="",M20=""),H20="吊飾",0)) + (IF(AND(A19="",M19="",A20="",M20="",A21="",M21=""),H21="吊飾",0)) + (IF(AND(A19="",M19="",A20="",M20="",A21="",M21="",A22="",M22=""),H22="吊飾",0)) + (IF(AND(A19="",M19="",A20="",M20="",A21="",M21="",A22="",M22="",A23="",M23=""),H23="吊飾",0)) + (IF(AND(A19="",M19="",A20="",M20="",A21="",M21="",A22="",M22="",A23="",M23="",A24="",M24=""),H24="吊飾",0)) + (IF(AND(A19="",M19="",A20="",M20="",A21="",M21="",A22="",M22="",A23="",M23="",A24="",M24="",A25="",M25=""),H25="吊飾",0)) ) / 2 ) * 220 + MAX(0, ( (H18="鎖匙扣") + (IF(AND(A19="",M19=""),H19="鎖匙扣",0)) + (IF(AND(A19="",M19="",A20="",M20=""),H20="鎖匙扣",0)) + (IF(AND(A19="",M19="",A20="",M20="",A21="",M21=""),H21="鎖匙扣",0)) + (IF(AND(A19="",M19="",A20="",M20="",A21="",M21="",A22="",M22=""),H22="鎖匙扣",0)) + (IF(AND(A19="",M19="",A20="",M20="",A21="",M21="",A22="",M22="",A23="",M23=""),H23="鎖匙扣",0)) + (IF(AND(A19="",M19="",A20="",M20="",A21="",M21="",A22="",M22="",A23="",M23="",A24="",M24=""),H24="鎖匙扣",0)) + (IF(AND(A19="",M19="",A20="",M20="",A21="",M21="",A22="",M22="",A23="",M23="",A24="",M24="",A25="",M25=""),H25="鎖匙扣",0)) ) - 1 ) * 20 ), 0 )} -> 487 | P18: =IF(ISNUMBER(M18), M18 - N18 - (O18 + IF(AND(A19="",M19=""),O19,0) + IF(AND(A19="",M19="",A20="",M20=""),O20,0) + IF(AND(A19="",M19="",A20="",M20="",A21="",M21=""),O21,0) + IF(AND(A19="",M19="",A20="",M20="",A21="",M21="",A22="",M22=""),O22,0) + IF(AND(A19="",M19="",A20="",M20="",A21="",M21="",A22="",M22="",A23="",M23=""),O23,0) + IF(AND(A19="",M19="",A20="",M20="",A21="",M21="",A22="",M22="",A23="",M23="",A24="",M24=""),O24,0) + IF(AND(A19="",M19="",A20="",M20="",A21="",M21="",A22="",M22="",A23="",M23="",A24="",M24="",A25="",M25=""),O25,0) + IF(AND(A19="",M19="",A20="",M20="",A21="",M21="",A22="",M22="",A23="",M23="",A24="",M24="",A25="",M25="",A26="",M26=""),O26,0) + IF(AND(A19="",M19="",A20="",M20="",A21="",M21="",A22="",M22="",A23="",M23="",A24="",M24="",A25="",M25="",A26="",M26="",A27="",M27=""),O27,0) ), -N18 - O18 ) -> -487 | Q18: 1
A19: 7 | B19: 46051 | C19: 森蝶 | D19: ? | E19: ? | F19: 嬰兒 | G19: 手 | H19: 鎖匙扣 | I19: 不锈鋼 | J19: 5 | K19: 左腳 | L19: 第32批 | M19: 2500 | N19: {=IF(鎖售表[[#This Row],[產品]]="鎖匙扣", _xlfn.XLOOKUP(鎖售表[[#This Row],[對象]]&鎖售表[[#This Row],[材料]]&鎖售表[[#This Row],[數量]], 成本表_鎖匙扣!$A$2:$A$100&成本表_鎖匙扣!$C$2:$C$100&成本表_鎖匙扣!$D$2:$D$100, 成本表_鎖匙扣!$E$2:$E$100, 0), _xlfn.XLOOKUP(鎖售表[[#This Row],[對象]]&鎖售表[[#This Row],[產品]]&鎖售表[[#This Row],[材料]]&鎖售表[[#This Row],[數量]], 成本表_吊飾!$A$2:$A$100&成本表_吊飾!$B$2:$B$100&成本表_吊飾!$C$2:$C$100&成本表_吊飾!$D$2:$D$100, 成本表_吊飾!$E$2:$E$100, 0) ) + IF(ISNUMBER(M19), ( IF(AND(A20="",M20=""),N20,0) + IF(AND(A20="",M20="",A21="",M21=""),N21,0) + IF(AND(A20="",M20="",A21="",M21="",A22="",M22=""),N22,0) + IF(AND(A20="",M20="",A21="",M21="",A22="",M22="",A23="",M23=""),N23,0) + IF(AND(A20="",M20="",A21="",M21="",A22="",M22="",A23="",M23="",A24="",M24=""),N24,0) + IF(AND(A20="",M20="",A21="",M21="",A22="",M22="",A23="",M23="",A24="",M24="",A25="",M25=""),N25,0) + IF(AND(A20="",M20="",A21="",M21="",A22="",M22="",A23="",M23="",A24="",M24="",A25="",M25="",A26="",M26=""),N26,0) + IF(AND(A20="",M20="",A21="",M21="",A22="",M22="",A23="",M23="",A24="",M24="",A25="",M25="",A26="",M26="",A27="",M27=""),N27,0) ) - ( INT( ( (H19="吊飾") + (IF(AND(A20="",M20=""),H20="吊飾",0)) + (IF(AND(A20="",M20="",A21="",M21=""),H21="吊飾",0)) + (IF(AND(A20="",M20="",A21="",M21="",A22="",M22=""),H22="吊飾",0)) + (IF(AND(A20="",M20="",A21="",M21="",A22="",M22="",A23="",M23=""),H23="吊飾",0)) + (IF(AND(A20="",M20="",A21="",M21="",A22="",M22="",A23="",M23="",A24="",M24=""),H24="吊飾",0)) + (IF(AND(A20="",M20="",A21="",M21="",A22="",M22="",A23="",M23="",A24="",M24="",A25="",M25=""),H25="吊飾",0)) + (IF(AND(A20="",M20="",A21="",M21="",A22="",M22="",A23="",M23="",A24="",M24="",A25="",M25="",A26="",M26=""),H26="吊飾",0)) ) / 2 ) * 220 + MAX(0, ( (H19="鎖匙扣") + (IF(AND(A20="",M20=""),H20="鎖匙扣",0)) + (IF(AND(A20="",M20="",A21="",M21=""),H21="鎖匙扣",0)) + (IF(AND(A20="",M20="",A21="",M21="",A22="",M22=""),H22="鎖匙扣",0)) + (IF(AND(A20="",M20="",A21="",M21="",A22="",M22="",A23="",M23=""),H23="鎖匙扣",0)) + (IF(AND(A20="",M20="",A21="",M21="",A22="",M22="",A23="",M23="",A24="",M24=""),H24="鎖匙扣",0)) + (IF(AND(A20="",M20="",A21="",M21="",A22="",M22="",A23="",M23="",A24="",M24="",A25="",M25=""),H25="鎖匙扣",0)) + (IF(AND(A20="",M20="",A21="",M21="",A22="",M22="",A23="",M23="",A24="",M24="",A25="",M25="",A26="",M26=""),H26="鎖匙扣",0)) ) - 1 ) * 20 ), 0 )} -> 605 | P19: =IF(ISNUMBER(M19), M19 - N19 - (O19 + IF(AND(A20="",M20=""),O20,0) + IF(AND(A20="",M20="",A21="",M21=""),O21,0) + IF(AND(A20="",M20="",A21="",M21="",A22="",M22=""),O22,0) + IF(AND(A20="",M20="",A21="",M21="",A22="",M22="",A23="",M23=""),O23,0) + IF(AND(A20="",M20="",A21="",M21="",A22="",M22="",A23="",M23="",A24="",M24=""),O24,0) + IF(AND(A20="",M20="",A21="",M21="",A22="",M22="",A23="",M23="",A24="",M24="",A25="",M25=""),O25,0) + IF(AND(A20="",M20="",A21="",M21="",A22="",M22="",A23="",M23="",A24="",M24="",A25="",M25="",A26="",M26=""),O26,0) + IF(AND(A20="",M20="",A21="",M21="",A22="",M22="",A23="",M23="",A24="",M24="",A25="",M25="",A26="",M26="",A27="",M27=""),O27,0) + IF(AND(A20="",M20="",A21="",M21="",A22="",M22="",A23="",M23="",A24="",M24="",A25="",M25="",A26="",M26="",A27="",M27="",A28="",M28=""),O28,0) ), -N19 - O19 ) -> 1895 | Q19: 0
A20: 8 | B20: 46054 | C20: Micaela | D20: ? | E20: ? | F20: 嬰兒 | G20: 腳 | H20: 鎖匙扣 | I20: 不锈鋼 | J20: 4 | L20: 第32批 | M20: 2000 | N20: {=IF(鎖售表[[#This Row],[產品]]="鎖匙扣", _xlfn.XLOOKUP(鎖售表[[#This Row],[對象]]&鎖售表[[#This Row],[材料]]&鎖售表[[#This Row],[數量]], 成本表_鎖匙扣!$A$2:$A$100&成本表_鎖匙扣!$C$2:$C$100&成本表_鎖匙扣!$D$2:$D$100, 成本表_鎖匙扣!$E$2:$E$100, 0), _xlfn.XLOOKUP(鎖售表[[#This Row],[對象]]&鎖售表[[#This Row],[產品]]&鎖售表[[#This Row],[材料]]&鎖售表[[#This Row],[數量]], 成本表_吊飾!$A$2:$A$100&成本表_吊飾!$B$2:$B$100&成本表_吊飾!$C$2:$C$100&成本表_吊飾!$D$2:$D$100, 成本表_吊飾!$E$2:$E$100, 0) ) + IF(ISNUMBER(M20), ( IF(AND(A21="",M21=""),N21,0) + IF(AND(A21="",M21="",A22="",M22=""),N22,0) + IF(AND(A21="",M21="",A22="",M22="",A23="",M23=""),N23,0) + IF(AND(A21="",M21="",A22="",M22="",A23="",M23="",A24="",M24=""),N24,0) + IF(AND(A21="",M21="",A22="",M22="",A23="",M23="",A24="",M24="",A25="",M25=""),N25,0) + IF(AND(A21="",M21="",A22="",M22="",A23="",M23="",A24="",M24="",A25="",M25="",A26="",M26=""),N26,0) + IF(AND(A21="",M21="",A22="",M22="",A23="",M23="",A24="",M24="",A25="",M25="",A26="",M26="",A27="",M27=""),N27,0) + IF(AND(A21="",M21="",A22="",M22="",A23="",M23="",A24="",M24="",A25="",M25="",A26="",M26="",A27="",M27="",A28="",M28=""),N28,0) ) - ( INT( ( (H20="吊飾") + (IF(AND(A21="",M21=""),H21="吊飾",0)) + (IF(AND(A21="",M21="",A22="",M22=""),H22="吊飾",0)) + (IF(AND(A21="",M21="",A22="",M22="",A23="",M23=""),H23="吊飾",0)) + (IF(AND(A21="",M21="",A22="",M22="",A23="",M23="",A24="",M24=""),H24="吊飾",0)) + (IF(AND(A21="",M21="",A22="",M22="",A23="",M23="",A24="",M24="",A25="",M25=""),H25="吊飾",0)) + (IF(AND(A21="",M21="",A22="",M22="",A23="",M23="",A24="",M24="",A25="",M25="",A26="",M26=""),H26="吊飾",0)) + (IF(AND(A21="",M21="",A22="",M22="",A23="",M23="",A24="",M24="",A25="",M25="",A26="",M26="",A27="",M27=""),H27="吊飾",0)) ) / 2 ) * 220 + MAX(0, ( (H20="鎖匙扣") + (IF(AND(A21="",M21=""),H21="鎖匙扣",0)) + (IF(AND(A21="",M21="",A22="",M22=""),H22="鎖匙扣",0)) + (IF(AND(A21="",M21="",A22="",M22="",A23="",M23=""),H23="鎖匙扣",0)) + (IF(AND(A21="",M21="",A22="",M22="",A23="",M23="",A24="",M24=""),H24="鎖匙扣",0)) + (IF(AND(A21="",M21="",A22="",M22="",A23="",M23="",A24="",M24="",A25="",M25=""),H25="鎖匙扣",0)) + (IF(AND(A21="",M21="",A22="",M22="",A23="",M23="",A24="",M24="",A25="",M25="",A26="",M26=""),H26="鎖匙扣",0)) + (IF(AND(A21="",M21="",A22="",M22="",A23="",M23="",A24="",M24="",A25="",M25="",A26="",M26="",A27="",M27=""),H27="鎖匙扣",0)) ) - 1 ) * 20 ), 0 )} -> 500 | P20: =IF(ISNUMBER(M20), M20 - N20 - (O20 + IF(AND(A21="",M21=""),O21,0) + IF(AND(A21="",M21="",A22="",M22=""),O22,0) + IF(AND(A21="",M21="",A22="",M22="",A23="",M23=""),O23,0) + IF(AND(A21="",M21="",A22="",M22="",A23="",M23="",A24="",M24=""),O24,0) + IF(AND(A21="",M21="",A22="",M22="",A23="",M23="",A24="",M24="",A25="",M25=""),O25,0) + IF(AND(A21="",M21="",A22="",M22="",A23="",M23="",A24="",M24="",A25="",M25="",A26="",M26=""),O26,0) + IF(AND(A21="",M21="",A22="",M22="",A23="",M23="",A24="",M24="",A25="",M25="",A26="",M26="",A27="",M27=""),O27,0) + IF(AND(A21="",M21="",A22="",M22="",A23="",M23="",A24="",M24="",A25="",M25="",A26="",M26="",A27="",M27="",A28="",M28=""),O28,0) + IF(AND(A21="",M21="",A22="",M22="",A23="",M23="",A24="",M24="",A25="",M25="",A26="",M26="",A27="",M27="",A28="",M28="",A29="",M29=""),O29,0) ), -N20 - O20 ) -> 1500 | Q20: 0
